Workbook

Sheet Premissas
A1: ANTÉVIA — Premissas do Modelo Financeiro v1.0 | H1: Simples Nacional — Anexo III (2027–2028)
A3: Premissa | B3: Valor | C3: Unidade | D3: Tipo | E3: Status / observação | F3: Fonte | H3: RBT12 até (R$) | I3: Alíquota nominal | J3: Dedução (R$) | K3: Fonte
A4: Horizonte | B4: 12 | C4: trimestres | D4: Modelo | E4: 3 anos | F4: Sprint E6 | H4: 180000 | I4: 0.06 | J4: 0 | K4: Senado / LC 123
A5: Fee por viagem | B5: 100 | C5: R$/viagem | D5: Input | E5: Premissa não validada | F5: Sprint 4 | H5: 360000 | I5: 0.112 | J5: 9360 | K5: Senado / LC 123
A6: Taxa processamento fee | B6: 0.03 | C6: % fee | D6: Input | E6: Premissa gerencial v1 | F6: Hipótese Antévia | H6: 720000 | I6: 0.135 | J6: 17640 | K6: Senado / LC 123
A7: Perdas operacionais | B7: 0.01 | C7: % receita | D7: Input | E7: Premissa gerencial v1 | F7: Hipótese Antévia | H7: 1800000 | I7: 0.16 | J7: 35640 | K7: Senado / LC 123
A8: Reserva mínima A | B8: 16500 | C8: R$ | D8: Input | E8: 3 meses OPEX médio A1 | F8: Cálculo Antévia | H8: 3600000 | I8: 0.21 | J8: 125640 | K8: Senado / LC 123
A9: Reserva mínima B | B9: 53700 | C9: R$ | D9: Input | E9: 3 meses OPEX médio B1 | F9: Cálculo Antévia | H9: 4800000 | I9: 0.329 | J9: 648000 | K9: Senado / LC 123
A10: CAPEX A1 | B10: 8000 | C10: R$ | D10: Input | E10: Equipamentos | F10: Hipótese Antévia
A11: CAPEX A2 | B11: 24000 | C11: R$ | D11: Input | E11: Equipamentos + tecnologia | F11: Hipótese Antévia | H11: Fontes externas
A12: CAPEX A3 | B12: 48000 | C12: R$ | D12: Input | E12: Equipamentos + tecnologia | F12: Hipótese Antévia | H12: Simples 2027 / RTC | I12: https://www.gov.br/receitafederal/pt-br/assuntos/noticias/2026/agosto/cgsn-atualiza-regras-do-simples-nacional-para-adequacao-a-reforma-tributaria-do-consumo
A13: OPEX A1 | B13: 66000 | C13: R$/ano | D13: Input | E13: Founder-led | F13: Hipótese Antévia | H13: LC 214 — Agências de turismo | I13: https://planalto.gov.br/ccivil_03/leis/lcp/lcp214compilado.htm
A14: OPEX A2 | B14: 198800 | C14: R$/ano | D14: Input | E14: 1 FTE Ops/CS + founders | F14: Hipótese Antévia | H14: Anexo III 2027–2028 | I14: https://legis.senado.gov.br/norma/40180341/publicacao/40181117
A15: OPEX A3 | B15: 381600 | C15: R$/ano | D15: Input | E15: 2 FTE Ops/CS; comercial condicional excluído | F15: Hipótese Antévia
A16: OPEX B1 | B16: 214800 | C16: R$/ano | D16: Input | E16: 2 FTEs profissionais | F16: Hipótese Antévia
A17: OPEX B2 | B17: 324000 | C17: R$/ano | D17: Input | E17: Estrutura profissional v1 | F17: Hipótese Antévia
A18: OPEX B3 | B18: 477600 | C18: R$/ano | D18: Input | E18: 2 Ops/CS + comercial | F18: Hipótese Antévia
A19: Sweat equity A1 | B19: 148800 | C19: R$ | D19: Analítico | E19: Fora da DFC | F19: Cálculo Antévia
A20: Tributação-base | B20: Simples Nacional - Anexo III | C20: texto | D20: Input | E20: Enquadramento deve ser validado por contador | F20: LC 123 / alterações 2026
A21: Nota tributária: modelo usa Simples Nacional como base acadêmica. O enquadramento CNAE/Anexo e a opção de IBS/CBS devem ser validados antes da implementação.

Sheet Receita
A1: ANTÉVIA — Receita Tendencial Trimestral
A3: R$ mil | B3: T1 | C3: T2 | D3: T3 | E3: T4 | F3: T5 | G3: T6 | H3: T7 | I3: T8 | J3: T9 | K3: T10 | L3: T11 | M3: T12
A4: Receita tendencial | B4: 7.1 | C4: 14.2 | D4: 21.3 | E4: 28.4 | F4: 56.8 | G4: 65.3 | H4: 76.7 | I4: 85.2 | J4: 148.8 | K4: 171.1 | L4: 200.9 | M4: 223.2
A6: Ano | B6: Receita (R$ mil) | C6: Status | D6: Observação
A7: Ano 1 | B7: 71 | C7: Herdado | D7: Sprint 4
A8: Ano 2 | B8: 284 | C8: Herdado | D8: Sprint 4
A9: Ano 3 | B9: 744 | C9: Herdado | D9: Sprint 4
A11: A distribuição T1–T12 é uma premissa de trimestralização que preserva exatamente os totais anuais do Sprint 4; substituir pelos valores originais se disponibilizados.

Sheet DFC_A
A1: ANTÉVIA — DFC A (R$ mil)
A3: Linha | B3: T1 | C3: T2 | D3: T3 | E3: T4 | F3: T5 | G3: T6 | H3: T7 | I3: T8 | J3: T9 | K3: T10 | L3: T11 | M3: T12
A4: Receita operacional | B4: =Receita_v2!B30/1000 -> 7.1797753 | C4: =Receita_v2!C30/1000 -> 14.160112 | D4: =Receita_v2!D30/1000 -> 21.339888 | E4: =Receita_v2!E30/1000 -> 28.320225 | F4: =Receita_v2!F30/1000 -> 56.640449 | G4: =Receita_v2!G30/1000 -> 65.216292 | H4: =Receita_v2!H30/1000 -> 76.783708 | I4: =Receita_v2!I30/1000 -> 85.359551 | ... M4: =Receita_v2!M30/1000 -> 223.12017
A5: Taxas transacionais | B5: =-Receita_v2!B27*Premissas!$B$6/1000 -> -0.108 | C5: =-Receita_v2!C27*Premissas!$B$6/1000 -> -0.213 | D5: =-Receita_v2!D27*Premissas!$B$6/1000 -> -0.321 | E5: =-Receita_v2!E27*Premissas!$B$6/1000 -> -0.426 | F5: =-Receita_v2!F27*Premissas!$B$6/1000 -> -0.852 | G5: =-Receita_v2!G27*Premissas!$B$6/1000 -> -0.981 | H5: =-Receita_v2!H27*Premissas!$B$6/1000 -> -1.155 | I5: =-Receita_v2!I27*Premissas!$B$6/1000 -> -1.284 | ... M5: =-Receita_v2!M27*Premissas!$B$6/1000 -> -3.354
A6: Perdas operacionais | B6: =-B4*Premissas!$B$7 -> -0.071797753 | C6: =-C4*Premissas!$B$7 -> -0.14160112 | D6: =-D4*Premissas!$B$7 -> -0.21339888 | E6: =-E4*Premissas!$B$7 -> -0.28320225 | F6: =-F4*Premissas!$B$7 -> -0.56640449 | G6: =-G4*Premissas!$B$7 -> -0.65216292 | H6: =-H4*Premissas!$B$7 -> -0.76783708 | I6: =-I4*Premissas!$B$7 -> -0.85359551 | ... M6: =-M4*Premissas!$B$7 -> -2.2312017
A7: OPEX | B7: =-Premissas!$B$13/4/1000 -> -16.5 | C7: =-Premissas!$B$13/4/1000 -> -16.5 | D7: =-Premissas!$B$13/4/1000 -> -16.5 | E7: =-Premissas!$B$13/4/1000 -> -16.5 | F7: =-Premissas!$B$14/4/1000 -> -49.7 | G7: =-Premissas!$B$14/4/1000 -> -49.7 | H7: =-Premissas!$B$14/4/1000 -> -49.7 | I7: =-Premissas!$B$14/4/1000 -> -49.7 | J7: =-Premissas!$B$15/4/1000 -> -95.4 | K7: =-Premissas!$B$15/4/1000 -> -95.4 | L7: =-Premissas!$B$15/4/1000 -> -95.4 | M7: =-Premissas!$B$15/4/1000 -> -95.4
A8: Tributos (provisão modelada) | B8: =-Tributacao_v3!B9/1000 -> -0.43078652 | C8: =-Tributacao_v3!C9/1000 -> -0.84960674 | D8: =-Tributacao_v3!D9/1000 -> -1.2803933 | E8: =-Tributacao_v3!E9/1000 -> -1.6992135 | F8: =-Tributacao_v3!F9/1000 -> -3.398427 | G8: =-Tributacao_v3!G9/1000 -> -3.9129775 | H8: =-Tributacao_v3!H9/1000 -> -5.4331672 | I8: =-Tributacao_v3!I9/1000 -> -6.7470112 | ... M8: =-Tributacao_v3!M9/1000 -> -25.011052
A9: Fluxo operacional | B9: =SUM(B4:B8) -> -9.930809 | C9: =SUM(C4:C8) -> -3.5440955 | D9: =SUM(D4:D8) -> 3.0250955 | E9: =SUM(E4:E8) -> 9.411809 | F9: =SUM(F4:F8) -> 2.123618 | G9: =SUM(G4:G8) -> 9.9701517 | H9: =SUM(H4:H8) -> 19.727704 | I9: =SUM(I4:I8) -> 26.774944 | ... M9: =SUM(M4:M8) -> 97.123918
A10: CAPEX | B10: =-Premissas!$B$10/1000 -> -8 | C10: 0 | D10: 0 | E10: 0 | F10: =-Premissas!$B$11/1000 -> -24 | G10: 0 | H10: 0 | I10: 0 | J10: =-Premissas!$B$12/1000 -> -48 | K10: 0 | L10: 0 | M10: 0
A11: FCL pré-funding | B11: =SUM(B9:B10) -> -17.930809 | C11: =SUM(C9:C10) -> -3.5440955 | D11: =SUM(D9:D10) -> 3.0250955 | E11: =SUM(E9:E10) -> 9.411809 | F11: =SUM(F9:F10) -> -21.876382 | G11: =SUM(G9:G10) -> 9.9701517 | H11: =SUM(H9:H10) -> 19.727704 | I11: =SUM(I9:I10) -> 26.774944 | ... M11: =SUM(M9:M10) -> 97.123918
A12: Funding inicial | B12: =-MIN(0,MIN(B17:M17))+Premissas!$B$8/1000 -> 47.414382 | C12: 0 | D12: 0 | E12: 0 | F12: 0 | G12: 0 | H12: 0 | I12: 0 | J12: 0 | K12: 0 | L12: 0 | M12: 0
A13: Variação líquida de caixa | B13: =B11+B12 -> 29.483573 | C13: =C11+C12 -> -3.5440955 | D13: =D11+D12 -> 3.0250955 | E13: =E11+E12 -> 9.411809 | F13: =F11+F12 -> -21.876382 | G13: =G11+G12 -> 9.9701517 | H13: =H11+H12 -> 19.727704 | I13: =I11+I12 -> 26.774944 | ... M13: =M11+M12 -> 97.123918
A14: Caixa acumulado | B14: =B13 -> 29.483573 | C14: =B14+C13 -> 25.939478 | D14: =C14+D13 -> 28.964573 | E14: =D14+E13 -> 38.376382 | F14: =E14+F13 -> 16.5 | G14: =F14+G13 -> 26.470152 | H14: =G14+H13 -> 46.197855 | I14: =H14+I13 -> 72.972799 | J14: =I14+J13 -> 61.60729 | ... M14: =L14+M13 -> 292.50549
A17: Cumulativo pré-funding | B17: =B11 -> -17.930809 | C17: =B17+C11 -> -21.474904 | D17: =C17+D11 -> -18.449809 | E17: =D17+E11 -> -9.038 | F17: =E17+F11 -> -30.914382 | G17: =F17+G11 -> -20.94423 | H17: =G17+H11 -> -1.2165267 | I17: =H17+I11 -> 25.558417 | J17: =I17+J11 -> 14.192908 | ... M17: =L17+M11 -> 245.0911
A19: Tributos v3: vinculados à aba Tributacao_v3, usando Anexo III e alíquota efetiva por RBT12 aproximada trimestralmente. A apuração legal é mensal; o modelo serve à projeção econômico-financeira do E6.
A21: Receita agora vinculada à Receita_v2 bottom-up. O modelo reconcilia as receitas herdadas via drivers explícitos; fee/comissão continuam premissas a validar no MVP.

Sheet DFC_B
A1: ANTÉVIA — DFC B (R$ mil)
A3: Linha | B3: T1 | C3: T2 | D3: T3 | E3: T4 | F3: T5 | G3: T6 | H3: T7 | I3: T8 | J3: T9 | K3: T10 | L3: T11 | M3: T12
A4: Receita operacional | B4: =Receita_v2!B30/1000 -> 7.1797753 | C4: =Receita_v2!C30/1000 -> 14.160112 | D4: =Receita_v2!D30/1000 -> 21.339888 | E4: =Receita_v2!E30/1000 -> 28.320225 | F4: =Receita_v2!F30/1000 -> 56.640449 | G4: =Receita_v2!G30/1000 -> 65.216292 | H4: =Receita_v2!H30/1000 -> 76.783708 | I4: =Receita_v2!I30/1000 -> 85.359551 | ... M4: =Receita_v2!M30/1000 -> 223.12017
A5: Taxas transacionais | B5: =-Receita_v2!B27*Premissas!$B$6/1000 -> -0.108 | C5: =-Receita_v2!C27*Premissas!$B$6/1000 -> -0.213 | D5: =-Receita_v2!D27*Premissas!$B$6/1000 -> -0.321 | E5: =-Receita_v2!E27*Premissas!$B$6/1000 -> -0.426 | F5: =-Receita_v2!F27*Premissas!$B$6/1000 -> -0.852 | G5: =-Receita_v2!G27*Premissas!$B$6/1000 -> -0.981 | H5: =-Receita_v2!H27*Premissas!$B$6/1000 -> -1.155 | I5: =-Receita_v2!I27*Premissas!$B$6/1000 -> -1.284 | ... M5: =-Receita_v2!M27*Premissas!$B$6/1000 -> -3.354
A6: Perdas operacionais | B6: =-B4*Premissas!$B$7 -> -0.071797753 | C6: =-C4*Premissas!$B$7 -> -0.14160112 | D6: =-D4*Premissas!$B$7 -> -0.21339888 | E6: =-E4*Premissas!$B$7 -> -0.28320225 | F6: =-F4*Premissas!$B$7 -> -0.56640449 | G6: =-G4*Premissas!$B$7 -> -0.65216292 | H6: =-H4*Premissas!$B$7 -> -0.76783708 | I6: =-I4*Premissas!$B$7 -> -0.85359551 | ... M6: =-M4*Premissas!$B$7 -> -2.2312017
A7: OPEX | B7: =-Premissas!$B$16/4/1000 -> -53.7 | C7: =-Premissas!$B$16/4/1000 -> -53.7 | D7: =-Premissas!$B$16/4/1000 -> -53.7 | E7: =-Premissas!$B$16/4/1000 -> -53.7 | F7: =-Premissas!$B$17/4/1000 -> -81 | G7: =-Premissas!$B$17/4/1000 -> -81 | H7: =-Premissas!$B$17/4/1000 -> -81 | I7: =-Premissas!$B$17/4/1000 -> -81 | J7: =-Premissas!$B$18/4/1000 -> -119.4 | K7: =-Premissas!$B$18/4/1000 -> -119.4 | L7: =-Premissas!$B$18/4/1000 -> -119.4 | M7: =-Premissas!$B$18/4/1000 -> -119.4
A8: Tributos (provisão modelada) | B8: =-Tributacao_v3!B9/1000 -> -0.43078652 | C8: =-Tributacao_v3!C9/1000 -> -0.84960674 | D8: =-Tributacao_v3!D9/1000 -> -1.2803933 | E8: =-Tributacao_v3!E9/1000 -> -1.6992135 | F8: =-Tributacao_v3!F9/1000 -> -3.398427 | G8: =-Tributacao_v3!G9/1000 -> -3.9129775 | H8: =-Tributacao_v3!H9/1000 -> -5.4331672 | I8: =-Tributacao_v3!I9/1000 -> -6.7470112 | ... M8: =-Tributacao_v3!M9/1000 -> -25.011052
A9: Fluxo operacional | B9: =SUM(B4:B8) -> -47.130809 | C9: =SUM(C4:C8) -> -40.744096 | D9: =SUM(D4:D8) -> -34.174904 | E9: =SUM(E4:E8) -> -27.788191 | F9: =SUM(F4:F8) -> -29.176382 | G9: =SUM(G4:G8) -> -21.329848 | H9: =SUM(H4:H8) -> -11.572296 | I9: =SUM(I4:I8) -> -4.5250562 | ... M9: =SUM(M4:M8) -> 73.123918
A10: CAPEX | B10: =-Premissas!$B$10/1000 -> -8 | C10: 0 | D10: 0 | E10: 0 | F10: =-Premissas!$B$11/1000 -> -24 | G10: 0 | H10: 0 | I10: 0 | J10: =-Premissas!$B$12/1000 -> -48 | K10: 0 | L10: 0 | M10: 0
A11: FCL pré-funding | B11: =SUM(B9:B10) -> -55.130809 | C11: =SUM(C9:C10) -> -40.744096 | D11: =SUM(D9:D10) -> -34.174904 | E11: =SUM(E9:E10) -> -27.788191 | F11: =SUM(F9:F10) -> -53.176382 | G11: =SUM(G9:G10) -> -21.329848 | H11: =SUM(H9:H10) -> -11.572296 | I11: =SUM(I9:I10) -> -4.5250562 | ... M11: =SUM(M9:M10) -> 73.123918
A12: Funding inicial | B12: =-MIN(0,MIN(B17:M17))+Premissas!$B$9/1000 -> 337.50709 | C12: 0 | D12: 0 | E12: 0 | F12: 0 | G12: 0 | H12: 0 | I12: 0 | J12: 0 | K12: 0 | L12: 0 | M12: 0
A13: Variação líquida de caixa | B13: =B11+B12 -> 282.37628 | C13: =C11+C12 -> -40.744096 | D13: =D11+D12 -> -34.174904 | E13: =E11+E12 -> -27.788191 | F13: =F11+F12 -> -53.176382 | G13: =G11+G12 -> -21.329848 | H13: =H11+H12 -> -11.572296 | I13: =I11+I12 -> -4.5250562 | ... M13: =M11+M12 -> 73.123918
A14: Caixa acumulado | B14: =B13 -> 282.37628 | C14: =B14+C13 -> 241.63219 | D14: =C14+D13 -> 207.45728 | E14: =D14+E13 -> 179.66909 | F14: =E14+F13 -> 126.49271 | G14: =F14+G13 -> 105.16286 | H14: =G14+H13 -> 93.590566 | I14: =H14+I13 -> 89.065509 | J14: =I14+J13 -> 53.7 | ... M14: =L14+M13 -> 212.5982
A17: Cumulativo pré-funding | B17: =B11 -> -55.130809 | C17: =B17+C11 -> -95.874904 | D17: =C17+D11 -> -130.04981 | E17: =D17+E11 -> -157.838 | F17: =E17+F11 -> -211.01438 | G17: =F17+G11 -> -232.34423 | H17: =G17+H11 -> -243.91653 | I17: =H17+I11 -> -248.44158 | J17: =I17+J11 -> -283.80709 | ... M17: =L17+M11 -> -124.9089
A19: Tributos v3: vinculados à aba Tributacao_v3, usando Anexo III e alíquota efetiva por RBT12 aproximada trimestralmente. A apuração legal é mensal; o modelo serve à projeção econômico-financeira do E6.
A21: Receita agora vinculada à Receita_v2 bottom-up. O modelo reconcilia as receitas herdadas via drivers explícitos; fee/comissão continuam premissas a validar no MVP.

Sheet Resumo
A1: ANTÉVIA — Resumo A × B
A3: Indicador | B3: A — Bootstrap | C3: B — Angel | E3: Valuation pre-money (R$ mil) | F3: Aporte B (R$ mil) | G3: Post-money | H3: Diluição
A4: Funding inicial (R$ mil) | B4: =DFC_A!B12 -> 47.414382 | C4: =DFC_B!B12 -> 337.50709 | E4: 1000 | F4: =DFC_B!B12 -> 337.50709 | G4: =E4+F4 -> 1337.5071 | H4: =F4/G4 -> 0.25234041
A5: Caixa final T12 (R$ mil) | B5: =DFC_A!M14 -> 292.50549 | C5: =DFC_B!M14 -> 212.5982 | E5: 1500 | F5: =DFC_B!B12 -> 337.50709 | G5: =E5+F5 -> 1837.5071 | H5: =F5/G5 -> 0.18367662
A6: FCL pré-funding 3 anos (R$ mil) | B6: =SUM(DFC_A!B11:M11) -> 245.0911 | C6: =SUM(DFC_B!B11:M11) -> -124.9089 | E6: 2000 | F6: =DFC_B!B12 -> 337.50709 | G6: =E6+F6 -> 2337.5071 | H6: =F6/G6 -> 0.14438762
A7: Sweat equity A1 (R$ mil) | B7: =Premissas!B19/1000 -> 148.8 | C7: 0
A8: Staff profissional A1 | B8: Founder-led | C8: 2 FTEs
A9: Dívida | B9: Não | C9: Não
A10: Diluição | B10: Não | C10: Sim
A12: Caixa acumulado | B12: T1 | C12: T2 | D12: T3 | E12: T4 | F12: T5 | G12: T6 | H12: T7 | I12: T8 | J12: T9 | K12: T10 | L12: T11 | M12: T12
A13: A | B13: =DFC_A!B14 -> 29.483573 | C13: =DFC_A!C14 -> 25.939478 | D13: =DFC_A!D14 -> 28.964573 | E13: =DFC_A!E14 -> 38.376382 | F13: =DFC_A!F14 -> 16.5 | G13: =DFC_A!G14 -> 26.470152 | H13: =DFC_A!H14 -> 46.197855 | I13: =DFC_A!I14 -> 72.972799 | ... M13: =DFC_A!M14 -> 292.50549
A14: B | B14: =DFC_B!B14 -> 282.37628 | C14: =DFC_B!C14 -> 241.63219 | D14: =DFC_B!D14 -> 207.45728 | E14: =DFC_B!E14 -> 179.66909 | F14: =DFC_B!F14 -> 126.49271 | G14: =DFC_B!G14 -> 105.16286 | H14: =DFC_B!H14 -> 93.590566 | I14: =DFC_B!I14 -> 89.065509 | ... M14: =DFC_B!M14 -> 212.5982
A16: Tributação v3 | B16: A — Bootstrap | C16: B — Angel
A17: DAS Ano 1 (R$ mil) | B17: =Tributacao_v3!C13/1000 -> 4.26 | C17: =Tributacao_v3!C13/1000 -> 4.26
A18: DAS Ano 2 (R$ mil) | B18: =Tributacao_v3!C14/1000 -> 19.491583 | C18: =Tributacao_v3!C14/1000 -> 19.491583
A19: DAS Ano 3 (R$ mil) | B19: =Tributacao_v3!C15/1000 -> 76.243312 | C19: =Tributacao_v3!C15/1000 -> 76.243312
A20: Carga efetiva A3 | B20: =Tributacao_v3!D15 -> 0.10247757 | C20: =Tributacao_v3!D15 -> 0.10247757

Sheet Sensibilidade
A1: Sensibilidades prioritárias — Antévia
A3: Variável | B3: Pessimista | C3: Tendencial | D3: Otimista | E3: Impacto esperado | F3: Status
A4: Fee (R$) | B4: 50 | C4: 100 | D4: 150 | E4: Receita / margem | F4: Sprint 4
A5: Tempo humano/viagem (min) | B5: 30 | C5: 20 | D5: 15 | E5: Headcount / OPEX | F5: Premissa
A6: Perdas operacionais | B6: 0.02 | C6: 0.01 | D6: 0.005 | E6: FCL | F6: Premissa
A7: Touchless rate | B7: 0.6 | C7: 0.8 | D7: 0.9 | E7: Capacidade operacional | F7: Premissa

Sheet Receita_v2
A1: ANTÉVIA — Receita v2 Bottom-up e Reconciliação
A3: Driver | B3: Ano 1 | C3: Ano 2 | D3: Ano 3 | E3: Unidade | F3: Natureza | G3: Observação | H3: Fonte/Status | I3: Fórmula-chave | J3: Validação | O3: Controle | P3: Resultado | Q3: Status
A4: Escolas parceiras | B4: 2 | C4: 5 | D4: 10 | E4: escolas | F4: Input E6 | G4: Ramp-up comercial | H4: Premissa E6 | I4: driver | O4: Viagens 3 anos | P4: =SUM(B23:M23) -> 5508 | Q4: =IF(P4=5508,"OK","REVER") -> OK
A5: Alunos elegíveis / escola | B5: 100 | C5: 100 | D5: 100 | E5: alunos | F5: Input E6 | G5: Base endereçável por escola | H5: Premissa E6 | I5: driver | O5: Receita A1 | P5: =SUM(B30:E30) -> 71000 | Q5: =IF(ABS(P5-B17)<1,"OK","REVER") -> OK
A6: Taxa de adesão | B6: 0.5 | C6: 0.6 | D6: 0.65 | E6: % | F6: Input E6 | G6: Conversão elegível → ativo | H6: Premissa E6 | I6: driver | O6: Receita A2 | P6: =SUM(F30:I30) -> 284000 | Q6: =IF(ABS(P6-C17)<1,"OK","REVER") -> OK
A7: Alunos ativos | B7: =B4*B5*B6 -> 100 | C7: =C4*C5*C6 -> 300 | D7: =D4*D5*D6 -> 650 | E7: alunos | F7: Cálculo | G7: Escolas × elegíveis × adesão | H7: Calculado | I7: escolas x elegíveis x adesão | O7: Receita A3 | P7: =SUM(J30:M30) -> 744000 | Q7: =IF(ABS(P7-D17)<1,"OK","REVER") -> OK
A8: Viagens monetizadas | B8: 356 | C8: 1424 | D8: 3728 | E8: viagens | F8: Input de reconciliação | G8: Total 3 anos = 5.508 | H8: Referência herdada | I8: referência
A9: Viagens / aluno ativo | B9: =B8/B7 -> 3.56 | C9: =C8/C7 -> 4.7466667 | D9: =D8/D7 -> 5.7353846 | E9: x | F9: Cálculo | G9: Intensidade de uso | H9: Calculado | I9: viagens / alunos ativos
A10: Fee médio | B10: 100 | C10: 100 | D10: 100 | E10: R$/viagem | F10: Input E6 | G10: Ponto médio da hipótese R$50–150 | H10: Projeto / hipótese | I10: premissa | O10: Unit economics | P10: Valor tendencial | Q10: Unidade
A11: Ticket médio GMV | B11: =(B17/B8-B10)/B12 -> 1988.764 | C11: =(C17/C8-C10)/C12 -> 1988.764 | D11: =(D17/D8-D10)/D12 -> 1991.4163 | E11: R$/viagem | F11: Cálculo de reconciliação | G11: Ticket implícito com comissão de 5% | H11: Calculado | I11: receita-alvo / viagens | O11: Fee / viagem | P11: =B10 -> 100 | Q11: R$
A12: Comissão média fornecedor | B12: 0.05 | C12: 0.05 | D12: 0.05 | E12: % GMV | F12: Input E6 | G12: Hipótese de monetização B2B | H12: Premissa E6 | I12: premissa | O12: Ticket GMV / viagem | P12: =AVERAGE(B11:D11) -> 1989.6481 | Q12: R$
A13: Receita fee | B13: =B8*B10 -> 35600 | C13: =C8*C10 -> 142400 | D13: =D8*D10 -> 372800 | E13: R$ | F13: Cálculo | G13: Viagens × fee | H13: Calculado | I13: viagens x fee | O13: Comissão | P13: =B12 -> 0.05 | Q13: % GMV
A14: GMV intermediado | B14: =B8*B11 -> 708000 | C14: =C8*C11 -> 2832000 | D14: =D8*D11 -> 7424000 | E14: R$ | F14: Cálculo | G14: Viagens × ticket médio | H14: Calculado | I14: viagens x ticket | O14: Receita / viagem | P14: =B16/B8 -> 199.4382 | Q14: R$
A15: Receita comissão | B15: =B14*B12 -> 35400 | C15: =C14*C12 -> 141600 | D15: =D14*D12 -> 371200 | E15: R$ | F15: Cálculo | G15: GMV × comissão | H15: Calculado | I15: GMV x comissão | O15: Custo processamento / viagem | P15: =P11*Premissas!B6 -> 3 | Q15: R$
A16: Receita bottom-up | B16: =B13+B15 -> 71000 | C16: =C13+C15 -> 284000 | D16: =D13+D15 -> 744000 | E16: R$ | F16: Cálculo | G16: Fee + comissão | H16: Calculado | I16: fee + comissão | O16: Margem antes OPEX / viagem | P16: =P14-P15-P14*Premissas!B7 -> 194.44382 | Q16: R$
A17: Receita herdada | B17: 71000 | C17: 284000 | D17: 744000 | E17: R$ | F17: Benchmark | G17: Sprint anterior | H17: Referência herdada | I17: benchmark
A18: Gap reconciliação | B18: =B16-B17 -> 0 | C18: =C16-C17 -> 0 | D18: =D16-D17 -> 0 | E18: R$ | F18: Cálculo | G18: Bottom-up – herdada | H18: Calculado | I18: bottom-up - herdada | O18: ATENÇÃO: escolas, base elegível, adesão, fee e comissão são premissas E6. O ticket médio (~R$1,99 mil) é o valor implícito necessário para reconciliar as receitas herdadas com fee de R$100 e comissão de 5%.
A19: Gap % | B19: =B18/B17 -> 0 | C19: =C18/C17 -> 0 | D19: =D18/D17 -> 0 | E19: % | F19: Cálculo | G19: Gap / receita herdada | H19: Calculado | I19: gap / herdada
A22: R$ / viagens | B22: T1 | C22: T2 | D22: T3 | E22: T4 | F22: T5 | G22: T6 | H22: T7 | I22: T8 | J22: T9 | K22: T10 | L22: T11 | M22: T12
A23: Viagens monetizadas | B23: 36 | C23: 71 | D23: 107 | E23: 142 | F23: 284 | G23: 327 | H23: 385 | I23: 428 | J23: 746 | K23: 857 | L23: 1007 | M23: 1118
A24: Fee médio | B24: =B10 -> 100 | C24: =B10 -> 100 | D24: =B10 -> 100 | E24: =B10 -> 100 | F24: =C10 -> 100 | G24: =C10 -> 100 | H24: =C10 -> 100 | I24: =C10 -> 100 | J24: =D10 -> 100 | K24: =D10 -> 100 | L24: =D10 -> 100 | M24: =D10 -> 100
A25: Ticket médio GMV | B25: =B11 -> 1988.764 | C25: =B11 -> 1988.764 | D25: =B11 -> 1988.764 | E25: =B11 -> 1988.764 | F25: =C11 -> 1988.764 | G25: =C11 -> 1988.764 | H25: =C11 -> 1988.764 | I25: =C11 -> 1988.764 | J25: =D11 -> 1991.4163 | K25: =D11 -> 1991.4163 | L25: =D11 -> 1991.4163 | M25: =D11 -> 1991.4163
A26: Comissão média | B26: =B12 -> 0.05 | C26: =B12 -> 0.05 | D26: =B12 -> 0.05 | E26: =B12 -> 0.05 | F26: =C12 -> 0.05 | G26: =C12 -> 0.05 | H26: =C12 -> 0.05 | I26: =C12 -> 0.05 | J26: =D12 -> 0.05 | K26: =D12 -> 0.05 | L26: =D12 -> 0.05 | M26: =D12 -> 0.05
A27: Receita fee | B27: =B23*B24 -> 3600 | C27: =C23*C24 -> 7100 | D27: =D23*D24 -> 10700 | E27: =E23*E24 -> 14200 | F27: =F23*F24 -> 28400 | G27: =G23*G24 -> 32700 | H27: =H23*H24 -> 38500 | I27: =I23*I24 -> 42800 | ... M27: =M23*M24 -> 111800
A28: GMV intermediado | B28: =B23*B25 -> 71595.506 | C28: =C23*C25 -> 141202.25 | D28: =D23*D25 -> 212797.75 | E28: =E23*E25 -> 282404.49 | F28: =F23*F25 -> 564808.99 | G28: =G23*G25 -> 650325.84 | H28: =H23*H25 -> 765674.16 | I28: =I23*I25 -> 851191.01 | ... M28: =M23*M25 -> 2226403.4
A29: Receita comissão | B29: =B28*B26 -> 3579.7753 | C29: =C28*C26 -> 7060.1124 | D29: =D28*D26 -> 10639.888 | E29: =E28*E26 -> 14120.225 | F29: =F28*F26 -> 28240.449 | G29: =G28*G26 -> 32516.292 | H29: =H28*H26 -> 38283.708 | I29: =I28*I26 -> 42559.551 | ... M29: =M28*M26 -> 111320.17
A30: Receita bottom-up | B30: =B27+B29 -> 7179.7753 | C30: =C27+C29 -> 14160.112 | D30: =D27+D29 -> 21339.888 | E30: =E27+E29 -> 28320.225 | F30: =F27+F29 -> 56640.449 | G30: =G27+G29 -> 65216.292 | H30: =H27+H29 -> 76783.708 | I30: =I27+I29 -> 85359.551 | ... M30: =M27+M29 -> 223120.17
A33: Leitura: a reconciliação fecha com fee de R$100 + comissão de 5% sobre GMV e ticket médio implícito de aproximadamente R$1.990 por viagem. Escolas, elegíveis, adesão, fee e comissão são premissas E6; 5.508 viagens e receitas anuais são referências herdadas. O ticket é calculado, não assumido, para testar a consistência econômica da projeção.

Sheet Tributacao_v3
A1: ANTÉVIA — Tributação v3 | Simples Nacional — Anexo III
A3: Linha | B3: T1 | C3: T2 | D3: T3 | E3: T4 | F3: T5 | G3: T6 | H3: T7 | I3: T8 | J3: T9 | K3: T10 | L3: T11 | M3: T12
A4: Receita trimestral (R$) | B4: =Receita_v2!B30 -> 7179.7753 | C4: =Receita_v2!C30 -> 14160.112 | D4: =Receita_v2!D30 -> 21339.888 | E4: =Receita_v2!E30 -> 28320.225 | F4: =Receita_v2!F30 -> 56640.449 | G4: =Receita_v2!G30 -> 65216.292 | H4: =Receita_v2!H30 -> 76783.708 | I4: =Receita_v2!I30 -> 85359.551 | ... M4: =Receita_v2!M30 -> 223120.17
A5: RBT12 de referência (R$) | B5: =SUM(B4:B4)*4/1 -> 28719.101 | C5: =SUM(B4:C4)*4/2 -> 42679.775 | D5: =SUM(B4:D4)*4/3 -> 56906.367 | E5: =SUM(B4:E4)*4/4 -> 71000 | F5: =SUM(C4:F4) -> 120460.67 | G5: =SUM(D4:G4) -> 171516.85 | H5: =SUM(E4:H4) -> 226960.67 | I5: =SUM(F4:I4) -> 284000 | J5: =SUM(G4:J4) -> 376239.38 | K5: =SUM(H4:K4) -> 482055.28 | L5: =SUM(I4:L4) -> 606239.38 | M5: =SUM(J4:M4) -> 744000
A6: Alíquota nominal | B6: =IF(B5<=180000,6%,IF(B5<=360000,11.2%,IF(B5<=720000,13.5%,IF(B5<=1800000,16%,IF(B5<=3600000,21%,32.9%))))) -> 0.06 | C6: =IF(C5<=180000,6%,IF(C5<=360000,11.2%,IF(C5<=720000,13.5%,IF(C5<=1800000,16%,IF(C5<=3600000,21%,32.9%))))) -> 0.06 | D6: =IF(D5<=180000,6%,IF(D5<=360000,11.2%,IF(D5<=720000,13.5%,IF(D5<=1800000,16%,IF(D5<=3600000,21%,32.9%))))) -> 0.06 | E6: =IF(E5<=180000,6%,IF(E5<=360000,11.2%,IF(E5<=720000,13.5%,IF(E5<=1800000,16%,IF(E5<=3600000,21%,32.9%))))) -> 0.06 | F6: =IF(F5<=180000,6%,IF(F5<=360000,11.2%,IF(F5<=720000,13.5%,IF(F5<=1800000,16%,IF(F5<=3600000,21%,32.9%))))) -> 0.06 | G6: =IF(G5<=180000,6%,IF(G5<=360000,11.2%,IF(G5<=720000,13.5%,IF(G5<=1800000,16%,IF(G5<=3600000,21%,32.9%))))) -> 0.06 | H6: =IF(H5<=180000,6%,IF(H5<=360000,11.2%,IF(H5<=720000,13.5%,IF(H5<=1800000,16%,IF(H5<=3600000,21%,32.9%))))) -> 0.112 | I6: =IF(I5<=180000,6%,IF(I5<=360000,11.2%,IF(I5<=720000,13.5%,IF(I5<=1800000,16%,IF(I5<=3600000,21%,32.9%))))) -> 0.112 | ... M6: =IF(M5<=180000,6%,IF(M5<=360000,11.2%,IF(M5<=720000,13.5%,IF(M5<=1800000,16%,IF(M5<=3600000,21%,32.9%))))) -> 0.16
A7: Parcela a deduzir (R$) | B7: =IF(B5<=180000,0,IF(B5<=360000,9360,IF(B5<=720000,17640,IF(B5<=1800000,35640,IF(B5<=3600000,125640,648000))))) -> 0 | C7: =IF(C5<=180000,0,IF(C5<=360000,9360,IF(C5<=720000,17640,IF(C5<=1800000,35640,IF(C5<=3600000,125640,648000))))) -> 0 | D7: =IF(D5<=180000,0,IF(D5<=360000,9360,IF(D5<=720000,17640,IF(D5<=1800000,35640,IF(D5<=3600000,125640,648000))))) -> 0 | E7: =IF(E5<=180000,0,IF(E5<=360000,9360,IF(E5<=720000,17640,IF(E5<=1800000,35640,IF(E5<=3600000,125640,648000))))) -> 0 | F7: =IF(F5<=180000,0,IF(F5<=360000,9360,IF(F5<=720000,17640,IF(F5<=1800000,35640,IF(F5<=3600000,125640,648000))))) -> 0 | G7: =IF(G5<=180000,0,IF(G5<=360000,9360,IF(G5<=720000,17640,IF(G5<=1800000,35640,IF(G5<=3600000,125640,648000))))) -> 0 | H7: =IF(H5<=180000,0,IF(H5<=360000,9360,IF(H5<=720000,17640,IF(H5<=1800000,35640,IF(H5<=3600000,125640,648000))))) -> 9360 | I7: =IF(I5<=180000,0,IF(I5<=360000,9360,IF(I5<=720000,17640,IF(I5<=1800000,35640,IF(I5<=3600000,125640,648000))))) -> 9360 | ... M7: =IF(M5<=180000,0,IF(M5<=360000,9360,IF(M5<=720000,17640,IF(M5<=1800000,35640,IF(M5<=3600000,125640,648000))))) -> 35640
A8: Alíquota efetiva | B8: =(B5*B6-B7)/B5 -> 0.06 | C8: =(C5*C6-C7)/C5 -> 0.06 | D8: =(D5*D6-D7)/D5 -> 0.06 | E8: =(E5*E6-E7)/E5 -> 0.06 | F8: =(F5*F6-F7)/F5 -> 0.06 | G8: =(G5*G6-G7)/G5 -> 0.06 | H8: =(H5*H6-H7)/H5 -> 0.070759375 | I8: =(I5*I6-I7)/I5 -> 0.079042254 | ... M8: =(M5*M6-M7)/M5 -> 0.11209677
A9: DAS estimado trimestre (R$) | B9: =B4*B8 -> 430.78652 | C9: =C4*C8 -> 849.60674 | D9: =D4*D8 -> 1280.3933 | E9: =E4*E8 -> 1699.2135 | F9: =F4*F8 -> 3398.427 | G9: =G4*G8 -> 3912.9775 | H9: =H4*H8 -> 5433.1672 | I9: =I4*I8 -> 6747.0112 | ... M9: =M4*M8 -> 25011.052
A12: Ano | B12: Receita | C12: DAS estimado | D12: Alíquota efetiva média | E12: Observação
A13: Ano 1 | B13: =SUM(B4:E4) -> 71000 | C13: =SUM(B9:E9) -> 4260 | D13: =C13/B13 -> 0.06 | E13: Anexo III — proxy trimestral RBT12
A14: Ano 2 | B14: =SUM(F4:I4) -> 284000 | C14: =SUM(F9:I9) -> 19491.583 | D14: =C14/B14 -> 0.068632334 | E14: Anexo III — proxy trimestral RBT12
A15: Ano 3 | B15: =SUM(J4:M4) -> 744000 | C15: =SUM(J9:M9) -> 76243.312 | D15: =C15/B15 -> 0.10247757 | E15: Anexo III — proxy trimestral RBT12
A18: Premissa-base E6: agência de viagem/turismo no Simples Nacional, Anexo III, sem Fator R. A apuração acima é uma aproximação trimestral para projeção acadêmica: a obrigação real é mensal e deve considerar a RBT12 e regras de início de atividade do PGDAS-D. A partir de 2027 IBS/CBS integram o Simples; a empresa pode optar pelo recolhimento regular desses tributos. A LC 214/2025 prevê regime específico para intermediação turística, deduzindo da base de IBS/CBS os valores repassados aos fornecedores intermediados e incluindo comissões/incentivos.
A23: Fonte | B23: Referência | C23: Uso no modelo
A24: Receita Federal — Perguntão Simples | B24: Agência de viagem e turismo: Anexo III, sem Fator R | C24: Enquadramento-base
A25: LC 123 — Anexo III 2027–2028 | B25: Faixas 6%; 11,2%; 13,5%; 16%; 21%; 32,9% | C25: Cálculo da alíquota efetiva
A26: LC 214/2025, art. 289 | B26: Regime específico de intermediação turística | C26: Base IBS/CBS
A27: Receita Federal — Res. CGSN 190/191 | B27: IBS/CBS incorporados ao Simples a partir de 2027 | C27: Reforma tributária
A28: Receita Federal — regime de caixa | B28: Apuração mensal passa a reconhecer receita por faturamento | C28: Capital de giro / ressalva

Sheet Stress_Test
A1: ANTÉVIA — Stress Test A × B | Pessimista • Tendencial • Otimista
A3: Driver | B3: Pessimista | C3: Tendencial | D3: Otimista | E3: Unidade | F3: Interpretação | G3: Status | I3: Cenário | J3: Funding A | K3: Caixa final A | L3: Funding B | M3: Caixa final B | N3: Receita 3a | O3: FCL A | P3: FCL B | Q3: Status
A4: Volume de viagens vs. base | B4: 0.7 | C4: 1 | D4: 1.2 | E4: x | F4: Adesão/uso agregado | G4: Premissa E6 | I4: Pessimista | J4: =E12 -> 356.11498 | K4: =M25+E12 -> 18.15 | L4: =F12 -> 804.03498 | M4: =M26+F12 -> 59.07 | N4: =SUM(B12:D12)/1000 -> 519.3929 | O4: =SUM(B23:M23) -> -337.96498 | P4: =SUM(B24:M24) -> -744.96498 | Q4: =IF(M4>0,"Sobrevive","Rever") -> Sobrevive
A5: Fee vs. base | B5: 0.75 | C5: 1 | D5: 1.25 | E5: x | F5: R$75 / R$100 / R$125 | G5: Premissa E6 | I5: Tendencial | J5: =E13 -> 47.757151 | K5: =M30+E13 -> 292.85429 | L5: =F13 -> 339.71036 | M5: =M31+F13 -> 214.80749 | N5: =SUM(B13:D13)/1000 -> 1099 | O5: =SUM(B28:M28) -> 245.09713 | P5: =SUM(B29:M29) -> -124.90287 | Q5: =IF(M5>0,"Sobrevive","Rever") -> Sobrevive
A6: Comissão vs. base | B6: 0.6 | C6: 1 | D6: 1.2 | E6: x | F6: 3% / 5% / 6% do GMV | G6: Premissa E6 | I6: Otimista | J6: =E14 -> 29.751076 | K6: =M35+E14 -> 771.41359 | L6: =F14 -> 191.96517 | M6: =M36+F14 -> 582.12768 | N6: =SUM(B14:D14)/1000 -> 1615.5959 | O6: =SUM(B33:M33) -> 741.66251 | P6: =SUM(B34:M34) -> 390.16251 | Q6: =IF(M6>0,"Sobrevive","Rever") -> Sobrevive
A7: OPEX vs. base | B7: 1.1 | C7: 1 | D7: 0.95 | E7: x | F7: Pressão/eficiência de custos | G7: Premissa E6
A8: Perdas operacionais | B8: 0.02 | C8: 0.01 | D8: 0.005 | E8: % receita | F8: Chargebacks/compensações | G8: Premissa E6
I9: Cenário | J9: Funding A | K9: Funding B | L9: Receita 3 anos
I10: Pessimista | J10: =J4 -> 356.11498 | K10: =L4 -> 804.03498 | L10: =N4 -> 519.3929
A11: Cenário | B11: Receita A1 | C11: Receita A2 | D11: Receita A3 | E11: Funding A | F11: Funding B | G11: Leitura | I11: Tendencial | J11: =J5 -> 47.757151 | K11: =L5 -> 339.71036 | L11: =N5 -> 1099
A12: Pessimista | B12: =71000*$B$4*(0.501*$B$5+0.499*$B$6) -> 33554.955 | C12: =284000*$B$4*(0.501*$B$5+0.499*$B$6) -> 134219.82 | D12: =744000*$B$4*(0.501*$B$5+0.499*$B$6) -> 351618.12 | E12: =-MIN(0,MIN(B25:M25))+16.5*$B$7 -> 356.11498 | F12: =-MIN(0,MIN(B26:M26))+53.7*$B$7 -> 804.03498 | G12: =IF(F12>500,"Capital intensivo","Dentro da faixa analisável") -> Capital intensivo | I12: Otimista | J12: =J6 -> 29.751076 | K12: =L6 -> 191.96517 | L12: =N6 -> 1615.5959
A13: Tendencial | B13: =71000*$C$4*(0.501*$C$5+0.499*$C$6) -> 71000 | C13: =284000*$C$4*(0.501*$C$5+0.499*$C$6) -> 284000 | D13: =744000*$C$4*(0.501*$C$5+0.499*$C$6) -> 744000 | E13: =-MIN(0,MIN(B30:M30))+16.5*$C$7 -> 47.757151 | F13: =-MIN(0,MIN(B31:M31))+53.7*$C$7 -> 339.71036 | G13: =IF(F13>500,"Capital intensivo","Dentro da faixa analisável") -> Dentro da faixa analisável
A14: Otimista | B14: =71000*$D$4*(0.501*$D$5+0.499*$D$6) -> 104374.26 | C14: =284000*$D$4*(0.501*$D$5+0.499*$D$6) -> 417497.04 | D14: =744000*$D$4*(0.501*$D$5+0.499*$D$6) -> 1093724.6 | E14: =-MIN(0,MIN(B35:M35))+16.5*$D$7 -> 29.751076 | F14: =-MIN(0,MIN(B36:M36))+53.7*$D$7 -> 191.96517 | G14: =IF(F14>500,"Capital intensivo","Dentro da faixa analisável") -> Dentro da faixa analisável
A17: Stress test gerencial: os choques são aplicados aos drivers econômicos, preservando a estrutura A/B. A tributação usa as cargas efetivas médias da v3 como aproximação; para decisão real, cada cenário deve ser recalculado mensalmente no PGDAS-D. O objetivo aqui é testar robustez, não produzir apuração fiscal.
A22: Pessimista | B22: T1 | C22: T2 | D22: T3 | E22: T4 | F22: T5 | G22: T6 | H22: T7 | I22: T8 | J22: T9 | K22: T10 | L22: T11 | M22: T12
A23: FCL A | B23: =(B12*0.1-(B12*0.1*0.501*$B$5/(0.501*$B$5+0.499*$B$6)*3%)-(B12*0.1*$B$8)-(B12*0.1*0.06)-(66000/4*$B$7)-8000)/1000 -> -23.118968 | C23: =(B12*0.2-(B12*0.2*0.501*$B$5/(0.501*$B$5+0.499*$B$6)*3%)-(B12*0.2*$B$8)-(B12*0.2*0.06)-(66000/4*$B$7)-0)/1000 -> -12.087937 | D23: =(B12*0.3-(B12*0.3*0.501*$B$5/(0.501*$B$5+0.499*$B$6)*3%)-(B12*0.3*$B$8)-(B12*0.3*0.06)-(66000/4*$B$7)-0)/1000 -> -9.0569054 | E23: =(B12*0.4-(B12*0.4*0.501*$B$5/(0.501*$B$5+0.499*$B$6)*3%)-(B12*0.4*$B$8)-(B12*0.4*0.06)-(66000/4*$B$7)-0)/1000 -> -6.0258739 | F23: =(C12*0.2-(C12*0.2*0.501*$B$5/(0.501*$B$5+0.499*$B$6)*3%)-(C12*0.2*$B$8)-(C12*0.2*0.0686323342495684)-(198800/4*$B$7)-24000)/1000 -> -54.653474 | G23: =(C12*0.23-(C12*0.23*0.501*$B$5/(0.501*$B$5+0.499*$B$6)*3%)-(C12*0.23*$B$8)-(C12*0.23*0.0686323342495684)-(198800/4*$B$7)-0)/1000 -> -27.050995 | H23: =(C12*0.27-(C12*0.27*0.501*$B$5/(0.501*$B$5+0.499*$B$6)*3%)-(C12*0.27*$B$8)-(C12*0.27*0.0686323342495684)-(198800/4*$B$7)-0)/1000 -> -22.24769 | I23: =(C12*0.3-(C12*0.3*0.501*$B$5/(0.501*$B$5+0.499*$B$6)*3%)-(C12*0.3*$B$8)-(C12*0.3*0.0686323342495684)-(198800/4*$B$7)-0)/1000 -> -18.645211 | J23: =(D12*0.2-(D12*0.2*0.501*$B$5/(0.501*$B$5+0.499*$B$6)*3%)-(D12*0.2*$B$8)-(D12*0.2*0.102477570147266)-(381600/4*$B$7)-48000)/1000 -> -92.403586 | K23: =(D12*0.23-(D12*0.23*0.501*$B$5/(0.501*$B$5+0.499*$B$6)*3%)-(D12*0.23*$B$8)-(D12*0.23*0.102477570147266)-(381600/4*$B$7)-0)/1000 -> -35.323124 | L23: =(D12*0.27-(D12*0.27*0.501*$B$5/(0.501*$B$5+0.499*$B$6)*3%)-(D12*0.27*$B$8)-(D12*0.27*0.102477570147266)-(381600/4*$B$7)-0)/1000 -> -23.215841 | M23: =(D12*0.3-(D12*0.3*0.501*$B$5/(0.501*$B$5+0.499*$B$6)*3%)-(D12*0.3*$B$8)-(D12*0.3*0.102477570147266)-(381600/4*$B$7)-0)/1000 -> -14.135379
A24: FCL B | B24: =(B12*0.1-(B12*0.1*0.501*$B$5/(0.501*$B$5+0.499*$B$6)*3%)-(B12*0.1*$B$8)-(B12*0.1*0.06)-(214800/4*$B$7)-8000)/1000 -> -64.038968 | C24: =(B12*0.2-(B12*0.2*0.501*$B$5/(0.501*$B$5+0.499*$B$6)*3%)-(B12*0.2*$B$8)-(B12*0.2*0.06)-(214800/4*$B$7)-0)/1000 -> -53.007937 | D24: =(B12*0.3-(B12*0.3*0.501*$B$5/(0.501*$B$5+0.499*$B$6)*3%)-(B12*0.3*$B$8)-(B12*0.3*0.06)-(214800/4*$B$7)-0)/1000 -> -49.976905 | E24: =(B12*0.4-(B12*0.4*0.501*$B$5/(0.501*$B$5+0.499*$B$6)*3%)-(B12*0.4*$B$8)-(B12*0.4*0.06)-(214800/4*$B$7)-0)/1000 -> -46.945874 | F24: =(C12*0.2-(C12*0.2*0.501*$B$5/(0.501*$B$5+0.499*$B$6)*3%)-(C12*0.2*$B$8)-(C12*0.2*0.0686323342495684)-(324000/4*$B$7)-24000)/1000 -> -89.083474 | G24: =(C12*0.23-(C12*0.23*0.501*$B$5/(0.501*$B$5+0.499*$B$6)*3%)-(C12*0.23*$B$8)-(C12*0.23*0.0686323342495684)-(324000/4*$B$7)-0)/1000 -> -61.480995 | H24: =(C12*0.27-(C12*0.27*0.501*$B$5/(0.501*$B$5+0.499*$B$6)*3%)-(C12*0.27*$B$8)-(C12*0.27*0.0686323342495684)-(324000/4*$B$7)-0)/1000 -> -56.67769 | I24: =(C12*0.3-(C12*0.3*0.501*$B$5/(0.501*$B$5+0.499*$B$6)*3%)-(C12*0.3*$B$8)-(C12*0.3*0.0686323342495684)-(324000/4*$B$7)-0)/1000 -> -53.075211 | J24: =(D12*0.2-(D12*0.2*0.501*$B$5/(0.501*$B$5+0.499*$B$6)*3%)-(D12*0.2*$B$8)-(D12*0.2*0.102477570147266)-(477600/4*$B$7)-48000)/1000 -> -118.80359 | K24: =(D12*0.23-(D12*0.23*0.501*$B$5/(0.501*$B$5+0.499*$B$6)*3%)-(D12*0.23*$B$8)-(D12*0.23*0.102477570147266)-(477600/4*$B$7)-0)/1000 -> -61.723124 | L24: =(D12*0.27-(D12*0.27*0.501*$B$5/(0.501*$B$5+0.499*$B$6)*3%)-(D12*0.27*$B$8)-(D12*0.27*0.102477570147266)-(477600/4*$B$7)-0)/1000 -> -49.615841 | M24: =(D12*0.3-(D12*0.3*0.501*$B$5/(0.501*$B$5+0.499*$B$6)*3%)-(D12*0.3*$B$8)-(D12*0.3*0.102477570147266)-(477600/4*$B$7)-0)/1000 -> -40.535379
A25: Cum A | B25: =B23 -> -23.118968 | C25: =B25+C23 -> -35.206905 | D25: =C25+D23 -> -44.263811 | E25: =D25+E23 -> -50.289685 | F25: =E25+F23 -> -104.94316 | G25: =F25+G23 -> -131.99415 | H25: =G25+H23 -> -154.24184 | I25: =H25+I23 -> -172.88705 | J25: =I25+J23 -> -265.29064 | ... M25: =L25+M23 -> -337.96498
A26: Cum B | B26: =B24 -> -64.038968 | C26: =B26+C24 -> -117.04691 | D26: =C26+D24 -> -167.02381 | E26: =D26+E24 -> -213.96968 | F26: =E26+F24 -> -303.05316 | G26: =F26+G24 -> -364.53415 | H26: =G26+H24 -> -421.21184 | I26: =H26+I24 -> -474.28705 | J26: =I26+J24 -> -593.09064 | ... M26: =L26+M24 -> -744.96498
A27: Tendencial | B27: T1 | C27: T2 | D27: T3 | E27: T4 | F27: T5 | G27: T6 | H27: T7 | I27: T8 | J27: T9 | K27: T10 | L27: T11 | M27: T12
A28: FCL A | B28: =(B13*0.1-(B13*0.1*0.501*$C$5/(0.501*$C$5+0.499*$C$6)*3%)-(B13*0.1*$C$8)-(B13*0.1*0.06)-(66000/4*$C$7)-8000)/1000 -> -18.003713 | C28: =(B13*0.2-(B13*0.2*0.501*$C$5/(0.501*$C$5+0.499*$C$6)*3%)-(B13*0.2*$C$8)-(B13*0.2*0.06)-(66000/4*$C$7)-0)/1000 -> -3.507426 | D28: =(B13*0.3-(B13*0.3*0.501*$C$5/(0.501*$C$5+0.499*$C$6)*3%)-(B13*0.3*$C$8)-(B13*0.3*0.06)-(66000/4*$C$7)-0)/1000 -> 2.988861 | E28: =(B13*0.4-(B13*0.4*0.501*$C$5/(0.501*$C$5+0.499*$C$6)*3%)-(B13*0.4*$C$8)-(B13*0.4*0.06)-(66000/4*$C$7)-0)/1000 -> 9.485148 | F28: =(C13*0.2-(C13*0.2*0.501*$C$5/(0.501*$C$5+0.499*$C$6)*3%)-(C13*0.2*$C$8)-(C13*0.2*0.0686323342495684)-(198800/4*$C$7)-24000)/1000 -> -22.220021 | G28: =(C13*0.23-(C13*0.23*0.501*$C$5/(0.501*$C$5+0.499*$C$6)*3%)-(C13*0.23*$C$8)-(C13*0.23*0.0686323342495684)-(198800/4*$C$7)-0)/1000 -> 9.5019763 | H28: =(C13*0.27-(C13*0.27*0.501*$C$5/(0.501*$C$5+0.499*$C$6)*3%)-(C13*0.27*$C$8)-(C13*0.27*0.0686323342495684)-(198800/4*$C$7)-0)/1000 -> 19.797972 | I28: =(C13*0.3-(C13*0.3*0.501*$C$5/(0.501*$C$5+0.499*$C$6)*3%)-(C13*0.3*$C$8)-(C13*0.3*0.0686323342495684)-(198800/4*$C$7)-0)/1000 -> 27.519969 | J28: =(D13*0.2-(D13*0.2*0.501*$C$5/(0.501*$C$5+0.499*$C$6)*3%)-(D13*0.2*$C$8)-(D13*0.2*0.102477570147266)-(381600/4*$C$7)-48000)/1000 -> -13.573126 | K28: =(D13*0.23-(D13*0.23*0.501*$C$5/(0.501*$C$5+0.499*$C$6)*3%)-(D13*0.23*$C$8)-(D13*0.23*0.102477570147266)-(381600/4*$C$7)-0)/1000 -> 53.900905 | L28: =(D13*0.27-(D13*0.27*0.501*$C$5/(0.501*$C$5+0.499*$C$6)*3%)-(D13*0.27*$C$8)-(D13*0.27*0.102477570147266)-(381600/4*$C$7)-0)/1000 -> 79.866279 | M28: =(D13*0.3-(D13*0.3*0.501*$C$5/(0.501*$C$5+0.499*$C$6)*3%)-(D13*0.3*$C$8)-(D13*0.3*0.102477570147266)-(381600/4*$C$7)-0)/1000 -> 99.34031
A29: FCL B | B29: =(B13*0.1-(B13*0.1*0.501*$C$5/(0.501*$C$5+0.499*$C$6)*3%)-(B13*0.1*$C$8)-(B13*0.1*0.06)-(214800/4*$C$7)-8000)/1000 -> -55.203713 | C29: =(B13*0.2-(B13*0.2*0.501*$C$5/(0.501*$C$5+0.499*$C$6)*3%)-(B13*0.2*$C$8)-(B13*0.2*0.06)-(214800/4*$C$7)-0)/1000 -> -40.707426 | D29: =(B13*0.3-(B13*0.3*0.501*$C$5/(0.501*$C$5+0.499*$C$6)*3%)-(B13*0.3*$C$8)-(B13*0.3*0.06)-(214800/4*$C$7)-0)/1000 -> -34.211139 | E29: =(B13*0.4-(B13*0.4*0.501*$C$5/(0.501*$C$5+0.499*$C$6)*3%)-(B13*0.4*$C$8)-(B13*0.4*0.06)-(214800/4*$C$7)-0)/1000 -> -27.714852 | F29: =(C13*0.2-(C13*0.2*0.501*$C$5/(0.501*$C$5+0.499*$C$6)*3%)-(C13*0.2*$C$8)-(C13*0.2*0.0686323342495684)-(324000/4*$C$7)-24000)/1000 -> -53.520021 | G29: =(C13*0.23-(C13*0.23*0.501*$C$5/(0.501*$C$5+0.499*$C$6)*3%)-(C13*0.23*$C$8)-(C13*0.23*0.0686323342495684)-(324000/4*$C$7)-0)/1000 -> -21.798024 | H29: =(C13*0.27-(C13*0.27*0.501*$C$5/(0.501*$C$5+0.499*$C$6)*3%)-(C13*0.27*$C$8)-(C13*0.27*0.0686323342495684)-(324000/4*$C$7)-0)/1000 -> -11.502028 | I29: =(C13*0.3-(C13*0.3*0.501*$C$5/(0.501*$C$5+0.499*$C$6)*3%)-(C13*0.3*$C$8)-(C13*0.3*0.0686323342495684)-(324000/4*$C$7)-0)/1000 -> -3.7800309 | J29: =(D13*0.2-(D13*0.2*0.501*$C$5/(0.501*$C$5+0.499*$C$6)*3%)-(D13*0.2*$C$8)-(D13*0.2*0.102477570147266)-(477600/4*$C$7)-48000)/1000 -> -37.573126 | K29: =(D13*0.23-(D13*0.23*0.501*$C$5/(0.501*$C$5+0.499*$C$6)*3%)-(D13*0.23*$C$8)-(D13*0.23*0.102477570147266)-(477600/4*$C$7)-0)/1000 -> 29.900905 | L29: =(D13*0.27-(D13*0.27*0.501*$C$5/(0.501*$C$5+0.499*$C$6)*3%)-(D13*0.27*$C$8)-(D13*0.27*0.102477570147266)-(477600/4*$C$7)-0)/1000 -> 55.866279 | M29: =(D13*0.3-(D13*0.3*0.501*$C$5/(0.501*$C$5+0.499*$C$6)*3%)-(D13*0.3*$C$8)-(D13*0.3*0.102477570147266)-(477600/4*$C$7)-0)/1000 -> 75.34031
A30: Cum A | B30: =B28 -> -18.003713 | C30: =B30+C28 -> -21.511139 | D30: =C30+D28 -> -18.522278 | E30: =D30+E28 -> -9.03713 | F30: =E30+F28 -> -31.257151 | G30: =F30+G28 -> -21.755174 | H30: =G30+H28 -> -1.957202 | I30: =H30+I28 -> 25.562767 | J30: =I30+J28 -> 11.989641 | ... M30: =L30+M28 -> 245.09713
A31: Cum B | B31: =B29 -> -55.203713 | C31: =B31+C29 -> -95.911139 | D31: =C31+D29 -> -130.12228 | E31: =D31+E29 -> -157.83713 | F31: =E31+F29 -> -211.35715 | G31: =F31+G29 -> -233.15517 | H31: =G31+H29 -> -244.6572 | I31: =H31+I29 -> -248.43723 | J31: =I31+J29 -> -286.01036 | ... M31: =L31+M29 -> -124.90287
A32: Otimista | B32: T1 | C32: T2 | D32: T3 | E32: T4 | F32: T5 | G32: T6 | H32: T7 | I32: T8 | J32: T9 | K32: T10 | L32: T11 | M32: T12
A33: FCL A | B33: =(B14*0.1-(B14*0.1*0.501*$D$5/(0.501*$D$5+0.499*$D$6)*3%)-(B14*0.1*$D$8)-(B14*0.1*0.06)-(66000/4*$D$7)-8000)/1000 -> -14.076076 | C33: =(B14*0.2-(B14*0.2*0.501*$D$5/(0.501*$D$5+0.499*$D$6)*3%)-(B14*0.2*$D$8)-(B14*0.2*0.06)-(66000/4*$D$7)-0)/1000 -> 3.5228476 | D33: =(B14*0.3-(B14*0.3*0.501*$D$5/(0.501*$D$5+0.499*$D$6)*3%)-(B14*0.3*$D$8)-(B14*0.3*0.06)-(66000/4*$D$7)-0)/1000 -> 13.121771 | E33: =(B14*0.4-(B14*0.4*0.501*$D$5/(0.501*$D$5+0.499*$D$6)*3%)-(B14*0.4*$D$8)-(B14*0.4*0.06)-(66000/4*$D$7)-0)/1000 -> 22.720695 | F33: =(C14*0.2-(C14*0.2*0.501*$D$5/(0.501*$D$5+0.499*$D$6)*3%)-(C14*0.2*$D$8)-(C14*0.2*0.0686323342495684)-(198800/4*$D$7)-24000)/1000 -> 4.8555957 | G33: =(C14*0.23-(C14*0.23*0.501*$D$5/(0.501*$D$5+0.499*$D$6)*3%)-(C14*0.23*$D$8)-(C14*0.23*0.0686323342495684)-(198800/4*$D$7)-0)/1000 -> 40.266185 | H33: =(C14*0.27-(C14*0.27*0.501*$D$5/(0.501*$D$5+0.499*$D$6)*3%)-(C14*0.27*$D$8)-(C14*0.27*0.0686323342495684)-(198800/4*$D$7)-0)/1000 -> 55.480304 | I33: =(C14*0.3-(C14*0.3*0.501*$D$5/(0.501*$D$5+0.499*$D$6)*3%)-(C14*0.3*$D$8)-(C14*0.3*0.0686323342495684)-(198800/4*$D$7)-0)/1000 -> 66.890894 | J33: =(D14*0.2-(D14*0.2*0.501*$D$5/(0.501*$D$5+0.499*$D$6)*3%)-(D14*0.2*$D$8)-(D14*0.2*0.102477570147266)-(381600/4*$D$7)-48000)/1000 -> 53.250059 | K33: =(D14*0.23-(D14*0.23*0.501*$D$5/(0.501*$D$5+0.499*$D$6)*3%)-(D14*0.23*$D$8)-(D14*0.23*0.102477570147266)-(381600/4*$D$7)-0)/1000 -> 130.03207 | L33: =(D14*0.27-(D14*0.27*0.501*$D$5/(0.501*$D$5+0.499*$D$6)*3%)-(D14*0.27*$D$8)-(D14*0.27*0.102477570147266)-(381600/4*$D$7)-0)/1000 -> 168.40808 | M33: =(D14*0.3-(D14*0.3*0.501*$D$5/(0.501*$D$5+0.499*$D$6)*3%)-(D14*0.3*$D$8)-(D14*0.3*0.102477570147266)-(381600/4*$D$7)-0)/1000 -> 197.19009
A34: FCL B | B34: =(B14*0.1-(B14*0.1*0.501*$D$5/(0.501*$D$5+0.499*$D$6)*3%)-(B14*0.1*$D$8)-(B14*0.1*0.06)-(214800/4*$D$7)-8000)/1000 -> -49.416076 | C34: =(B14*0.2-(B14*0.2*0.501*$D$5/(0.501*$D$5+0.499*$D$6)*3%)-(B14*0.2*$D$8)-(B14*0.2*0.06)-(214800/4*$D$7)-0)/1000 -> -31.817152 | D34: =(B14*0.3-(B14*0.3*0.501*$D$5/(0.501*$D$5+0.499*$D$6)*3%)-(B14*0.3*$D$8)-(B14*0.3*0.06)-(214800/4*$D$7)-0)/1000 -> -22.218229 | E34: =(B14*0.4-(B14*0.4*0.501*$D$5/(0.501*$D$5+0.499*$D$6)*3%)-(B14*0.4*$D$8)-(B14*0.4*0.06)-(214800/4*$D$7)-0)/1000 -> -12.619305 | F34: =(C14*0.2-(C14*0.2*0.501*$D$5/(0.501*$D$5+0.499*$D$6)*3%)-(C14*0.2*$D$8)-(C14*0.2*0.0686323342495684)-(324000/4*$D$7)-24000)/1000 -> -24.879404 | G34: =(C14*0.23-(C14*0.23*0.501*$D$5/(0.501*$D$5+0.499*$D$6)*3%)-(C14*0.23*$D$8)-(C14*0.23*0.0686323342495684)-(324000/4*$D$7)-0)/1000 -> 10.531185 | H34: =(C14*0.27-(C14*0.27*0.501*$D$5/(0.501*$D$5+0.499*$D$6)*3%)-(C14*0.27*$D$8)-(C14*0.27*0.0686323342495684)-(324000/4*$D$7)-0)/1000 -> 25.745304 | I34: =(C14*0.3-(C14*0.3*0.501*$D$5/(0.501*$D$5+0.499*$D$6)*3%)-(C14*0.3*$D$8)-(C14*0.3*0.0686323342495684)-(324000/4*$D$7)-0)/1000 -> 37.155894 | J34: =(D14*0.2-(D14*0.2*0.501*$D$5/(0.501*$D$5+0.499*$D$6)*3%)-(D14*0.2*$D$8)-(D14*0.2*0.102477570147266)-(477600/4*$D$7)-48000)/1000 -> 30.450059 | K34: =(D14*0.23-(D14*0.23*0.501*$D$5/(0.501*$D$5+0.499*$D$6)*3%)-(D14*0.23*$D$8)-(D14*0.23*0.102477570147266)-(477600/4*$D$7)-0)/1000 -> 107.23207 | L34: =(D14*0.27-(D14*0.27*0.501*$D$5/(0.501*$D$5+0.499*$D$6)*3%)-(D14*0.27*$D$8)-(D14*0.27*0.102477570147266)-(477600/4*$D$7)-0)/1000 -> 145.60808 | M34: =(D14*0.3-(D14*0.3*0.501*$D$5/(0.501*$D$5+0.499*$D$6)*3%)-(D14*0.3*$D$8)-(D14*0.3*0.102477570147266)-(477600/4*$D$7)-0)/1000 -> 174.39009
A35: Cum A | B35: =B33 -> -14.076076 | C35: =B35+C33 -> -10.553229 | D35: =C35+D33 -> 2.5685429 | E35: =D35+E33 -> 25.289238 | F35: =E35+F33 -> 30.144834 | G35: =F35+G33 -> 70.411019 | H35: =G35+H33 -> 125.89132 | I35: =H35+I33 -> 192.78222 | J35: =I35+J33 -> 246.03228 | ... M35: =L35+M33 -> 741.66251
A36: Cum B | B36: =B34 -> -49.416076 | C36: =B36+C34 -> -81.233229 | D36: =C36+D34 -> -103.45146 | E36: =D36+E34 -> -116.07076 | F36: =E36+F34 -> -140.95017 | G36: =F36+G34 -> -130.41898 | H36: =G36+H34 -> -104.67368 | I36: =H36+I34 -> -67.517783 | J36: =I36+J34 -> -37.067725 | ... M36: =L36+M34 -> 390.16251

Sheet DFC_Final_A
A1: ANTÉVIA — DFC Final E6 | Cenário A — Bootstrap / Founder-led | R$ mil
A3: Linha | B3: T1 | C3: T2 | D3: T3 | E3: T4 | F3: T5 | G3: T6 | H3: T7 | I3: T8 | J3: T9 | K3: T10 | L3: T11 | M3: T12
A4: ATIVIDADES OPERACIONAIS
A5: Receita Bruta | B5: =DFC_A!B4 -> 7.1797753 | C5: =DFC_A!C4 -> 14.160112 | D5: =DFC_A!D4 -> 21.339888 | E5: =DFC_A!E4 -> 28.320225 | F5: =DFC_A!F4 -> 56.640449 | G5: =DFC_A!G4 -> 65.216292 | H5: =DFC_A!H4 -> 76.783708 | I5: =DFC_A!I4 -> 85.359551 | ... M5: =DFC_A!M4 -> 223.12017
A6: (-) Impostos sobre receita | B6: =DFC_A!B8 -> -0.43078652 | C6: =DFC_A!C8 -> -0.84960674 | D6: =DFC_A!D8 -> -1.2803933 | E6: =DFC_A!E8 -> -1.6992135 | F6: =DFC_A!F8 -> -3.398427 | G6: =DFC_A!G8 -> -3.9129775 | H6: =DFC_A!H8 -> -5.4331672 | I6: =DFC_A!I8 -> -6.7470112 | ... M6: =DFC_A!M8 -> -25.011052
A7: (-) Custos transacionais | B7: =DFC_A!B5 -> -0.108 | C7: =DFC_A!C5 -> -0.213 | D7: =DFC_A!D5 -> -0.321 | E7: =DFC_A!E5 -> -0.426 | F7: =DFC_A!F5 -> -0.852 | G7: =DFC_A!G5 -> -0.981 | H7: =DFC_A!H5 -> -1.155 | I7: =DFC_A!I5 -> -1.284 | ... M7: =DFC_A!M5 -> -3.354
A8: (-) Perdas operacionais | B8: =DFC_A!B6 -> -0.071797753 | C8: =DFC_A!C6 -> -0.14160112 | D8: =DFC_A!D6 -> -0.21339888 | E8: =DFC_A!E6 -> -0.28320225 | F8: =DFC_A!F6 -> -0.56640449 | G8: =DFC_A!G6 -> -0.65216292 | H8: =DFC_A!H6 -> -0.76783708 | I8: =DFC_A!I6 -> -0.85359551 | ... M8: =DFC_A!M6 -> -2.2312017
A9: (=) Receita após tributos/custos variáveis | B9: =SUM(B5:B8) -> 6.569191 | C9: =SUM(C5:C8) -> 12.955904 | D9: =SUM(D5:D8) -> 19.525096 | E9: =SUM(E5:E8) -> 25.911809 | F9: =SUM(F5:F8) -> 51.823618 | G9: =SUM(G5:G8) -> 59.670152 | H9: =SUM(H5:H8) -> 69.427704 | I9: =SUM(I5:I8) -> 76.474944 | ... M9: =SUM(M5:M8) -> 192.52392
A10: (-) Custos de prestação / pessoal operacional | B10: =DFC_A!B7*0.65 -> -10.725 | C10: =DFC_A!C7*0.65 -> -10.725 | D10: =DFC_A!D7*0.65 -> -10.725 | E10: =DFC_A!E7*0.65 -> -10.725 | F10: =DFC_A!F7*0.65 -> -32.305 | G10: =DFC_A!G7*0.65 -> -32.305 | H10: =DFC_A!H7*0.65 -> -32.305 | I10: =DFC_A!I7*0.65 -> -32.305 | ... M10: =DFC_A!M7*0.65 -> -62.01
A11: (-) Despesas SG&A | B11: =DFC_A!B7*(1-0.65) -> -5.775 | C11: =DFC_A!C7*(1-0.65) -> -5.775 | D11: =DFC_A!D7*(1-0.65) -> -5.775 | E11: =DFC_A!E7*(1-0.65) -> -5.775 | F11: =DFC_A!F7*(1-0.65) -> -17.395 | G11: =DFC_A!G7*(1-0.65) -> -17.395 | H11: =DFC_A!H7*(1-0.65) -> -17.395 | I11: =DFC_A!I7*(1-0.65) -> -17.395 | ... M11: =DFC_A!M7*(1-0.65) -> -33.39
A12: (=) Resultado operacional de caixa | B12: =SUM(B9:B11) -> -9.930809 | C12: =SUM(C9:C11) -> -3.5440955 | D12: =SUM(D9:D11) -> 3.0250955 | E12: =SUM(E9:E11) -> 9.411809 | F12: =SUM(F9:F11) -> 2.123618 | G12: =SUM(G9:G11) -> 9.9701517 | H12: =SUM(H9:H11) -> 19.727704 | I12: =SUM(I9:I11) -> 26.774944 | ... M12: =SUM(M9:M11) -> 97.123918
A14: ATIVIDADES DE INVESTIMENTO
A15: (-) CAPEX / investimentos | B15: =DFC_A!B10 -> -8 | C15: =DFC_A!C10 -> 0 | D15: =DFC_A!D10 -> 0 | E15: =DFC_A!E10 -> 0 | F15: =DFC_A!F10 -> -24 | G15: =DFC_A!G10 -> 0 | H15: =DFC_A!H10 -> 0 | I15: =DFC_A!I10 -> 0 | ... M15: =DFC_A!M10 -> 0
A16: (=) Fluxo de Caixa Livre pré-financiamento | B16: =B12+B15 -> -17.930809 | C16: =C12+C15 -> -3.5440955 | D16: =D12+D15 -> 3.0250955 | E16: =E12+E15 -> 9.411809 | F16: =F12+F15 -> -21.876382 | G16: =G12+G15 -> 9.9701517 | H16: =H12+H15 -> 19.727704 | I16: =I12+I15 -> 26.774944 | ... M16: =M12+M15 -> 97.123918
A18: ATIVIDADES DE FINANCIAMENTO
A19: (+) Aporte de capital | B19: =DFC_A!B12 -> 47.414382 | C19: =DFC_A!C12 -> 0 | D19: =DFC_A!D12 -> 0 | E19: =DFC_A!E12 -> 0 | F19: =DFC_A!F12 -> 0 | G19: =DFC_A!G12 -> 0 | H19: =DFC_A!H12 -> 0 | I19: =DFC_A!I12 -> 0 | ... M19: =DFC_A!M12 -> 0
A20: (=) Variação líquida do caixa | B20: =B16+B19 -> 29.483573 | C20: =C16+C19 -> -3.5440955 | D20: =D16+D19 -> 3.0250955 | E20: =E16+E19 -> 9.411809 | F20: =F16+F19 -> -21.876382 | G20: =G16+G19 -> 9.9701517 | H20: =H16+H19 -> 19.727704 | I20: =I16+I19 -> 26.774944 | ... M20: =M16+M19 -> 97.123918
A21: (=) FC Acumulado | B21: =B20 -> 29.483573 | C21: =B21+C20 -> 25.939478 | D21: =C21+D20 -> 28.964573 | E21: =D21+E20 -> 38.376382 | F21: =E21+F20 -> 16.5 | G21: =F21+G20 -> 26.470152 | H21: =G21+H20 -> 46.197855 | I21: =H21+I20 -> 72.972799 | J21: =I21+J20 -> 61.60729 | ... M21: =L21+M20 -> 292.50549
A23: Nota de apresentação E6: a separação entre 'custos de prestação/pessoal operacional' e 'SG&A' usa uma alocação gerencial de 65% / 35% do OPEX do cenário A — Bootstrap / Founder-led. A DFC original preserva o OPEX total; esta abertura serve para aderir à estrutura acadêmica de Custos x Despesas. A alocação deve ser refinada quando houver folha e centros de custo definitivos.

Sheet DFC_Final_B
A1: ANTÉVIA — DFC Final E6 | Cenário B — Angel / Professional-led | R$ mil
A3: Linha | B3: T1 | C3: T2 | D3: T3 | E3: T4 | F3: T5 | G3: T6 | H3: T7 | I3: T8 | J3: T9 | K3: T10 | L3: T11 | M3: T12
A4: ATIVIDADES OPERACIONAIS
A5: Receita Bruta | B5: =DFC_B!B4 -> 7.1797753 | C5: =DFC_B!C4 -> 14.160112 | D5: =DFC_B!D4 -> 21.339888 | E5: =DFC_B!E4 -> 28.320225 | F5: =DFC_B!F4 -> 56.640449 | G5: =DFC_B!G4 -> 65.216292 | H5: =DFC_B!H4 -> 76.783708 | I5: =DFC_B!I4 -> 85.359551 | ... M5: =DFC_B!M4 -> 223.12017
A6: (-) Impostos sobre receita | B6: =DFC_B!B8 -> -0.43078652 | C6: =DFC_B!C8 -> -0.84960674 | D6: =DFC_B!D8 -> -1.2803933 | E6: =DFC_B!E8 -> -1.6992135 | F6: =DFC_B!F8 -> -3.398427 | G6: =DFC_B!G8 -> -3.9129775 | H6: =DFC_B!H8 -> -5.4331672 | I6: =DFC_B!I8 -> -6.7470112 | ... M6: =DFC_B!M8 -> -25.011052
A7: (-) Custos transacionais | B7: =DFC_B!B5 -> -0.108 | C7: =DFC_B!C5 -> -0.213 | D7: =DFC_B!D5 -> -0.321 | E7: =DFC_B!E5 -> -0.426 | F7: =DFC_B!F5 -> -0.852 | G7: =DFC_B!G5 -> -0.981 | H7: =DFC_B!H5 -> -1.155 | I7: =DFC_B!I5 -> -1.284 | ... M7: =DFC_B!M5 -> -3.354
A8: (-) Perdas operacionais | B8: =DFC_B!B6 -> -0.071797753 | C8: =DFC_B!C6 -> -0.14160112 | D8: =DFC_B!D6 -> -0.21339888 | E8: =DFC_B!E6 -> -0.28320225 | F8: =DFC_B!F6 -> -0.56640449 | G8: =DFC_B!G6 -> -0.65216292 | H8: =DFC_B!H6 -> -0.76783708 | I8: =DFC_B!I6 -> -0.85359551 | ... M8: =DFC_B!M6 -> -2.2312017
A9: (=) Receita após tributos/custos variáveis | B9: =SUM(B5:B8) -> 6.569191 | C9: =SUM(C5:C8) -> 12.955904 | D9: =SUM(D5:D8) -> 19.525096 | E9: =SUM(E5:E8) -> 25.911809 | F9: =SUM(F5:F8) -> 51.823618 | G9: =SUM(G5:G8) -> 59.670152 | H9: =SUM(H5:H8) -> 69.427704 | I9: =SUM(I5:I8) -> 76.474944 | ... M9: =SUM(M5:M8) -> 192.52392
A10: (-) Custos de prestação / pessoal operacional | B10: =DFC_B!B7*0.65 -> -34.905 | C10: =DFC_B!C7*0.65 -> -34.905 | D10: =DFC_B!D7*0.65 -> -34.905 | E10: =DFC_B!E7*0.65 -> -34.905 | F10: =DFC_B!F7*0.65 -> -52.65 | G10: =DFC_B!G7*0.65 -> -52.65 | H10: =DFC_B!H7*0.65 -> -52.65 | I10: =DFC_B!I7*0.65 -> -52.65 | ... M10: =DFC_B!M7*0.65 -> -77.61
A11: (-) Despesas SG&A | B11: =DFC_B!B7*(1-0.65) -> -18.795 | C11: =DFC_B!C7*(1-0.65) -> -18.795 | D11: =DFC_B!D7*(1-0.65) -> -18.795 | E11: =DFC_B!E7*(1-0.65) -> -18.795 | F11: =DFC_B!F7*(1-0.65) -> -28.35 | G11: =DFC_B!G7*(1-0.65) -> -28.35 | H11: =DFC_B!H7*(1-0.65) -> -28.35 | I11: =DFC_B!I7*(1-0.65) -> -28.35 | ... M11: =DFC_B!M7*(1-0.65) -> -41.79
A12: (=) Resultado operacional de caixa | B12: =SUM(B9:B11) -> -47.130809 | C12: =SUM(C9:C11) -> -40.744096 | D12: =SUM(D9:D11) -> -34.174904 | E12: =SUM(E9:E11) -> -27.788191 | F12: =SUM(F9:F11) -> -29.176382 | G12: =SUM(G9:G11) -> -21.329848 | H12: =SUM(H9:H11) -> -11.572296 | I12: =SUM(I9:I11) -> -4.5250562 | ... M12: =SUM(M9:M11) -> 73.123918
A14: ATIVIDADES DE INVESTIMENTO
A15: (-) CAPEX / investimentos | B15: =DFC_B!B10 -> -8 | C15: =DFC_B!C10 -> 0 | D15: =DFC_B!D10 -> 0 | E15: =DFC_B!E10 -> 0 | F15: =DFC_B!F10 -> -24 | G15: =DFC_B!G10 -> 0 | H15: =DFC_B!H10 -> 0 | I15: =DFC_B!I10 -> 0 | ... M15: =DFC_B!M10 -> 0
A16: (=) Fluxo de Caixa Livre pré-financiamento | B16: =B12+B15 -> -55.130809 | C16: =C12+C15 -> -40.744096 | D16: =D12+D15 -> -34.174904 | E16: =E12+E15 -> -27.788191 | F16: =F12+F15 -> -53.176382 | G16: =G12+G15 -> -21.329848 | H16: =H12+H15 -> -11.572296 | I16: =I12+I15 -> -4.5250562 | ... M16: =M12+M15 -> 73.123918
A18: ATIVIDADES DE FINANCIAMENTO
A19: (+) Aporte de capital | B19: =DFC_B!B12 -> 337.50709 | C19: =DFC_B!C12 -> 0 | D19: =DFC_B!D12 -> 0 | E19: =DFC_B!E12 -> 0 | F19: =DFC_B!F12 -> 0 | G19: =DFC_B!G12 -> 0 | H19: =DFC_B!H12 -> 0 | I19: =DFC_B!I12 -> 0 | ... M19: =DFC_B!M12 -> 0
A20: (=) Variação líquida do caixa | B20: =B16+B19 -> 282.37628 | C20: =C16+C19 -> -40.744096 | D20: =D16+D19 -> -34.174904 | E20: =E16+E19 -> -27.788191 | F20: =F16+F19 -> -53.176382 | G20: =G16+G19 -> -21.329848 | H20: =H16+H19 -> -11.572296 | I20: =I16+I19 -> -4.5250562 | ... M20: =M16+M19 -> 73.123918
A21: (=) FC Acumulado | B21: =B20 -> 282.37628 | C21: =B21+C20 -> 241.63219 | D21: =C21+D20 -> 207.45728 | E21: =D21+E20 -> 179.66909 | F21: =E21+F20 -> 126.49271 | G21: =F21+G20 -> 105.16286 | H21: =G21+H20 -> 93.590566 | I21: =H21+I20 -> 89.065509 | J21: =I21+J20 -> 53.7 | ... M21: =L21+M20 -> 212.5982
A23: Nota de apresentação E6: a separação entre 'custos de prestação/pessoal operacional' e 'SG&A' usa uma alocação gerencial de 65% / 35% do OPEX do cenário B — Angel / Professional-led. A DFC original preserva o OPEX total; esta abertura serve para aderir à estrutura acadêmica de Custos x Despesas. A alocação deve ser refinada quando houver folha e centros de custo definitivos.

Sheet Entregaveis_E6
A1: ANTÉVIA — Mapa de Entregáveis | Sprint E6
A3: Entregável do enunciado | B3: Situação | C3: Onde está | D3: Conteúdo-chave | E3: Premissa/GAP | F3: Vai ao Squeeze? | G3: Responsável | H3: Observação
A4: 1. Macroprocesso de negócio | B4: PARCIAL | C4: Material anterior / Squeeze | D4: Fluxo ponta a ponta da prestação | E4: Converter em visual final | F4: SIM | G4: Equipe | H4: Exigência explícita E6
A5: 2. Estrutura de pessoal | B5: PRONTO | C5: Premissas + DFC A/B | D5: Founder-led vs staff profissional | E5: Refinar cargos/salários se necessário | F5: SIM | G5: Equipe | H5: Evolução A1–A3
A6: 3. Custos, despesas e investimentos | B6: PRONTO | C6: Premissas + DFC_Final_A/B | D6: OPEX, custos variáveis, SG&A, CAPEX | E6: Alocação custos/SG&A é gerencial | F6: SIM | G6: Equipe | H6: 3 anos
A7: 4. DFC 3 anos | B7: PRONTO | C7: DFC_Final_A / DFC_Final_B | D7: Operação, investimento, financiamento | E7: Trimestral | F7: SIM | G7: Equipe | H7: 12 trimestres
A8: 3 cenários | B8: PRONTO | C8: Stress_Test | D8: Pessimista, tendencial, otimista | E8: Drivers explicitados | F8: SIM | G8: Equipe | H8: Exigência explícita E6
A9: Análise de sensibilidade | B9: PRONTO | C9: Stress_Test + Sensibilidade | D9: Volume, fee, comissão, OPEX, perdas | E9: Premissas E6 | F9: SIM | G9: Equipe | H9: Exigência explícita E6
A10: Memória de cálculo | B10: PRONTO | C10: Receita_v2 / Tributacao_v3 / Premissas | D10: Drivers auditáveis | E10: Hipóteses marcadas | F10: NÃO — apoio | G10: Equipe | H10: Munição para banca
A11: Financiamento A x B | B11: EXTRA | C11: Resumo / DFC A/B | D11: Bootstrap x Angel | E11: C descartado | F11: SIM — síntese | G11: Equipe | H11: Além do mínimo exigido
A13: Fonte do checklist: BD Sprint E6 — Resumo dos Entregáveis: macroprocesso; estrutura de pessoal; projeções de custos, despesas e investimentos; DFC por meses e/ou trimestres no período de 3 anos; e, no corpo da atividade, pelo menos três cenários com análise de sensibilidade.
A18: Slide | B18: Título | C18: Mensagem central | D18: Visual sugerido | E18: Números-chave | F18: Fonte na planilha | G18: Status | H18: Notas
A19: 1 | B19: Macroprocesso | C19: Como a Antévia entrega valor ponta a ponta | D19: Fluxo horizontal | E19: — | F19: Material macroprocesso | G19: PENDENTE | H19: Construir visual
A20: 2 | B20: Estrutura operacional | C20: A entrada founder-led reduz caixa; profissionalização compra capacidade | D20: Organograma A1→A3 | E20: A vs B | F20: Premissas | G20: PRONTO
A21: 3 | B21: Economia unitária | C21: Receita = fee + comissão, separada do GMV | D21: Waterfall por viagem | E21: ~R$100 fee + ~R$100 comissão | F21: Receita_v2 | G21: PRONTO
A22: 4 | B22: Custos, despesas e CAPEX | C22: Estrutura enxuta e escalável | D22: Barras por ano | E22: OPEX/CAPEX A/B | F22: Premissas | G22: PRONTO
A23: 5 | B23: DFC tendencial | C23: O bootstrap requer menos capital no cenário-base | D23: Curvas de caixa | E23: ~R$47–48k A; ~R$338–340k B | F23: DFC_Final_A/B | G23: PRONTO
A24: 6 | B24: Stress test | C24: A viabilidade é sensível à validação comercial | D24: 3 cenários | E24: Funding A/B por cenário | F24: Stress_Test | G24: PRONTO
A25: 7 | B25: Estrutura de capital | C25: Dívida foi testada e descartada; equity é capital paciente | D25: A vs B + nota C | E25: A founder-led; B angel | F25: Resumo | G25: PRONTO
A26: 8 | B26: Recomendação | C26: Começar A; migrar para B após marcos de validação | D26: Stage gates | E26: adesão, frequência, fee, comissão | F26: Stress_Test | G26: PRONTO

Sheet Cenarios_Oficiais_v6
A1: ANTÉVIA — Cenários Oficiais Recuperados do Sprint 04
A3: Cenário | B3: Ano 1 (R$) | C3: Ano 2 (R$) | D3: Ano 3 (R$) | E3: 3 anos (R$) | F3: Viagens 3 anos | G3: Alunos A1 | H3: Alunos T12
A4: Pessimista | B4: 38000 | C4: 140000 | D4: 372000 | E4: 550000 | F4: 2763 | G4: 50 | H4: 320
A5: Tendencial | B5: 71000 | C5: 284000 | D5: 744000 | E5: 1099000 | F5: 5508 | G5: 100 | H5: 650
A6: Otimista | B6: 113000 | C6: 455000 | D6: 1270000 | E6: 1838000 | F6: 9180 | G6: 160 | H6: 1100
A8: Fonte: trajetória da disciplina / Sprint 04 no deck compartilhado. A v6 restaura estes cenários como referência oficial. As variáveis 'escolas × elegíveis × adesão' introduzidas na v2 permanecem apenas como memória exploratória e NÃO são usadas na consolidação final.
A12: Driver oficial | B12: Pessimista | C12: Tendencial | D12: Otimista
A13: Alunos captados (referências A1/T12) | B13: 50 → 320 | C13: 100 → 650 | D13: 160 → 1.100
A14: Taxa de serviço | B14: Variável-chave | C14: Variável-chave | D14: Variável-chave
A15: Comissão | B15: Variável-chave | C15: Variável-chave | D15: Variável-chave
A17: Nota de fonte externa já validada no repositório: H6 (disposição a pagar R$50–150) segue 'a verificar'; portanto taxa de serviço e comissão devem permanecer hipóteses críticas, não fatos validados.

Sheet Viabilidade_S06
A1: ANTÉVIA — Sprint 06 | Indicadores de Viabilidade Econômico-Financeira
A3: Premissa | B3: Valor | C3: Unidade | D3: Status
A4: TMA anual | B4: 0.15 | C4: % a.a. | D4: Premissa E6/S06 — definir/validar
A5: TMA trimestral | B5: =(1+B4)^(1/4)-1 -> 0.035558076 | C5: % a.t. | D5: Calculada
A6: Horizonte | B6: 12 | C6: trimestres | D6: Sprint 06
A9: Indicador | B9: T1 | C9: T2 | D9: T3 | E9: T4 | F9: T5 | G9: T6 | H9: T7 | I9: T8 | J9: T9 | K9: T10 | L9: T11 | M9: T12 | N9: T0 | O9: T1 | P9: T2 | Q9: T3 | R9: T4 | S9: T5 | T9: T6 | U9: T7 | V9: T8 | W9: T9 | X9: T10 | Y9: T11 | Z9: T12
A10: FCL A — Tendencial (R$ mil) | B10: =DFC_Final_A!B16 -> -17.930809 | C10: =DFC_Final_A!C16 -> -3.5440955 | D10: =DFC_Final_A!D16 -> 3.0250955 | E10: =DFC_Final_A!E16 -> 9.411809 | F10: =DFC_Final_A!F16 -> -21.876382 | G10: =DFC_Final_A!G16 -> 9.9701517 | H10: =DFC_Final_A!H16 -> 19.727704 | I10: =DFC_Final_A!I16 -> 26.774944 | ... M10: =DFC_Final_A!M16 -> 97.123918 | N10: =-B15 -> -47.414382 | O10: =B10 -> -17.930809 | P10: =C10 -> -3.5440955 | Q10: =D10 -> 3.0250955 | R10: =E10 -> 9.411809 | S10: =F10 -> -21.876382 | T10: =G10 -> 9.9701517 | U10: =H10 -> 19.727704 | V10: =I10 -> 26.774944 | ... Z10: =M10 -> 97.123918
